diff --git a/config/joints.yaml b/config/joints.yaml
index 1301f62..494e9c3 100644
--- a/config/joints.yaml
+++ b/config/joints.yaml
@@ -4,20 +4,23 @@ joint_state_controller:
 
 camera_controller:
   type: "position_controllers/JointPositionController"
-  joint: chassis_to_camera
+  joint: base_to_camera
 
 front_left_wheel_controller:
   type: "velocity_controllers/JointVelocityController"
-  joint: chassis_to_front_left_wheel
+  joint: base_to_front_left_wheel
 
 front_right_wheel_controller:
   type: "velocity_controllers/JointVelocityController"
-  joint: chassis_to_front_right_wheel
+  joint: base_to_front_right_wheel
 
 back_left_wheel_controller:
   type: "velocity_controllers/JointVelocityController"
-  joint: chassis_to_back_left_wheel
+  joint: base_to_back_left_wheel
 
 back_right_wheel_controller:
   type: "velocity_controllers/JointVelocityController"
-  joint: chassis_to_back_right_wheel
+  joint: base_to_back_right_wheel
+
+
+
diff --git a/urdf/growbot.gazebo b/growbot.gazebo
similarity index 60%
rename from urdf/growbot.gazebo
rename to growbot.gazebo
index 00206a4..8692138 100644
--- a/urdf/growbot.gazebo
+++ b/growbot.gazebo
@@ -1,9 +1,6 @@
-<?xml version="1.0"?>
-<robot xmlns:xacro="http://www.ros.org/wiki/xacro" name="growbot">
-
   <!-- camera -->
   <gazebo reference="camera_link">
-    <sensor type="camera" name="camera">
+    <sensor type="camera" name="camera1">
       <update_rate>30.0</update_rate>
       <camera name="head">
         <horizontal_fov>1.3962634</horizontal_fov>
@@ -28,7 +25,7 @@
       <plugin name="camera_controller" filename="libgazebo_ros_camera.so">
         <alwaysOn>true</alwaysOn>
         <updateRate>0.0</updateRate>
-        <cameraName>growbot/camera0</cameraName>
+        <cameraName>growbot/camera1</cameraName>
         <imageTopicName>image_raw</imageTopicName>
         <cameraInfoTopicName>camera_info</cameraInfoTopicName>
         <frameName>camera_link</frameName>
@@ -41,41 +38,3 @@
       </plugin>
     </sensor>
   </gazebo>
-  
-      <gazebo reference="front_left_wheel">
-      <material>
-        Gazebo/Yellow
-      </material>
-  </gazebo> 
-  
-    <gazebo reference="front_right_wheel">
-      <material>
-        Gazebo/Yellow
-      </material>
-  </gazebo> 
-  
-    <gazebo reference="back_left_wheel">
-      <material>
-        Gazebo/Yellow
-      </material>
-  </gazebo> 
-  
-    <gazebo reference="back_right_wheel">
-      <material>
-        Gazebo/Yellow
-      </material>
-  </gazebo> 
-  
-      <gazebo reference="camera_link">
-      <material>
-        Gazebo/Black
-      </material>
-  </gazebo> 
-  
-        <gazebo reference="chassis_link">
-      <material>
-        Gazebo/Silver
-      </material>
-  </gazebo>
-  
-</robot>
diff --git a/launch/gazebo.launch b/launch/gazebo.launch
index 273748a..e23de44 100644
--- a/launch/gazebo.launch
+++ b/launch/gazebo.launch
@@ -24,7 +24,8 @@
         type="spawn_model"
         respawn="false"
         output="screen"
-        args="-x 5 -y 0 -Y 0
+        args="-z 1.0
+              -unpause
               -urdf
               -model growbot
               -param robot_description"/>
@@ -34,9 +35,8 @@
   <rosparam command="load"
             file="$(find growbot_simulations)/config/joints.yaml" />
   
-<!--ns="/growbot"-->
   <!-- Spawn controllers -->
-  <node name="controller_spawner"
+  <node name="bot_controller_spawner"
         pkg="controller_manager"
         type="spawner"
         args="joint_state_controller
@@ -45,4 +45,4 @@
               back_left_wheel_controller
               back_right_wheel_controller
               camera_controller" />
-</launch>
+</launch>
\ No newline at end of file
diff --git a/launch/spawn_growbot.launch b/launch/spawn_growbot.launch
index 4ef01fb..d9c2852 100644
--- a/launch/spawn_growbot.launch
+++ b/launch/spawn_growbot.launch
@@ -7,6 +7,6 @@
   <param name="robot_description" command="$(find xacro)/xacro --inorder $(find growbot_simulations)/urdf/main.xacro" />
 
   <!-- Spawn Growbot -->
-  <node name="urdf_spawner" pkg="gazebo_ros" type="spawn_model" respawn="false" output="screen"
-	      args="-unpause -urdf -model growbot -param robot_description -x $(arg x) -y $(arg y) -z $(arg z) -R 0 -P 0 -Y $(arg yaw)" />
+  <node name="urdf_spawner" pkg="gazebo_ros" type="spawn_model"
+	      args="-urdf -model growbot -param robot_description -x $(arg x) -y $(arg y) -z $(arg z) -R 0 -P 0 -Y $(arg yaw)" />
 </launch>
diff --git a/models/heightmap/model.sdf b/models/heightmap/model.sdf
index 5cbdb45..ba5bac5 100644
--- a/models/heightmap/model.sdf
+++ b/models/heightmap/model.sdf
@@ -7,7 +7,7 @@
         <geometry>
           <heightmap>
             <uri>model://heightmap/materials/textures/heightmap.png</uri>
-            <size>16 16 1</size>
+            <size>32 32 1</size>
             <pos>0 0 0</pos>
           </heightmap>
         </geometry>
@@ -40,7 +40,7 @@
               <fade_dist>0.5</fade_dist>
             </blend>
             <uri>model://heightmap/materials/textures/heightmap.png</uri>
-            <size>16 16 1</size>
+            <size>32 32 1</size>
             <pos>0 0 0</pos>
           </heightmap>
         </geometry>
diff --git a/package.xml b/package.xml
index 4dd7878..6f6a46a 100644
--- a/package.xml
+++ b/package.xml
@@ -15,7 +15,6 @@
   <exec_depend>position_controllers</exec_depend>
   <exec_depend>velocity_controllers</exec_depend>
   <exec_depend>robot_state_publisher</exec_depend>
-  <exec_depend>gazebo_plugins</exec_depend>
   <exec_depend>rqt_robot_steering</exec_depend>
   <exec_depend>rviz</exec_depend>
   <exec_depend>xacro</exec_depend>
diff --git a/rviz/urdf.rviz b/rviz/urdf.rviz
index 452e4e8..87547b6 100644
--- a/rviz/urdf.rviz
+++ b/rviz/urdf.rviz
@@ -11,32 +11,14 @@ Visualization Manager:
     - Alpha: 0.8
       Class: rviz/RobotModel
       Enabled: true
-      Name: growbot
+      Name: my_robot
       Robot Description: robot_description
       Value: true
     - Class: rviz/TF
       Name: TF
       Value: false
-    - Class: rviz/Camera
-      Enabled: true
-      Image Rendering: background and overlay
-      Image Topic: /growbot/camera0/image_raw
-      Name: Camera
-      Overlay Alpha: 0.5
-      Queue Size: 2
-      Transport Hint: raw
-      Unreliable: false
-      Value: true
-      Visibility:
-        Grid: true
-        Marker: true
-        Path: true
-        RobotModel: true
-        TF: true
-        Value: true
-      Zoom Factor: 1
   Global Options:
-    Fixed Frame: chassis_link
+    Fixed Frame: base_link
     Frame Rate: 30
   Name: root
   Tools:
diff --git a/urdf/camera.xacro b/urdf/camera.xacro
index d0ae77b..8c0ff98 100644
--- a/urdf/camera.xacro
+++ b/urdf/camera.xacro
@@ -1,22 +1,22 @@
 <?xml version="1.0"?>
-<robot xmlns:xacro="http://www.ros.org/wiki/xacro" name="growbot">
+<robot xmlns:xacro="http://www.ros.org/wiki/xacro" name="my_robot">
 <xacro:macro name="camera">
 
-    <xacro:property name="camera_size" value="0.05" /> <!-- Size of square 'camera' box -->
+    <xacro:property name="camera_link" value="0.05" /> <!-- Size of square 'camera' box -->
 
     <!-- Camera -->
   <link name="camera_link">
     <collision>
             <origin rpy="0 0 0" xyz="0 0 0"/>
       <geometry>
-    <box size="${camera_size} ${camera_size*2} ${camera_size}"/>
+    <box size="${camera_link} ${camera_link*2} ${camera_link}"/>
       </geometry>
     </collision>
 
     <visual>
             <origin rpy="0 0 0" xyz="0 0 0"/>
       <geometry>
-    <box size="${camera_size} ${camera_size*2} ${camera_size}"/>
+    <box size="${camera_link} ${camera_link*2} ${camera_link}"/>
       </geometry>
       <material name="black"/>
     </visual>
@@ -26,27 +26,14 @@
             <origin rpy="0 0 0" xyz="0 0 0"/>
       <inertia ixx="1e-6" ixy="0" ixz="0" iyy="1e-6" iyz="0" izz="1e-6" />
     </inertial>
-</link>
-
-  <!-- generate an optical frame http://www.ros.org/reps/rep-0103.html#suffix-frames
-      so that ros and opencv can operate on the camera frame correctly -->
-  <joint name="camera_optical_joint" type="fixed">
-    <!-- these values have to be these values otherwise the gazebo camera image
-        won't be aligned properly with the frame it is supposedly originating from -->
-    <origin xyz="0 0 0" rpy="${-pi/2} 0 ${-pi/2}"/>
-    <parent link="camera_link"/>
-    <child link="camera_link_optical"/>
-  </joint>
-
-  <link name="camera_link_optical">
   </link>
 
 
-    <joint name="chassis_to_camera" type="fixed">
+    <joint name="base_to_camera" type="continuous">
         <axis xyz="0 0 1"/>  <!-- changes axis of rotation -->
-        <parent link="chassis_link"/>
+        <parent link="base_link"/>
         <child link="camera_link"/>
-        <origin rpy="0 0 0" xyz="${camera_size/2 + 0.15} 0 ${camera_size/2 + 0.15}"/> <!-- moves the child_frame with respect to parent_frame -->
+        <origin rpy="0 0 0" xyz="0.15 0 ${camera_link/2 + 0.15}"/> <!-- moves the child_frame with respect to parent_frame -->
         <limit effort="30" velocity="1.0"/>
     </joint>
 
@@ -56,12 +43,54 @@
         <actuator name="$camera_motor">
             <mechanicalReduction>1</mechanicalReduction>
         </actuator>
-        <joint name="chassis_to_camera">
+        <joint name="base_to_camera">
             <hardwareInterface>hardware_interface/PositionJointInterface</hardwareInterface>
         </joint>
     </transmission>
 
+
 </xacro:macro>
 
- </robot>
+  <!--Gazebo Camera Plugin-->
+   <gazebo reference="camera">
+    <sensor type="camera" name="camera">
+      <update_rate>30.0</update_rate>
+      <camera name="head">
+        <horizontal_fov>1.3962634</horizontal_fov>
+        <image>
+          <width>800</width>
+          <height>800</height>
+          <format>R8G8B8</format>
+        </image>
+        <clip>
+          <near>0.02</near>
+          <far>300</far>
+        </clip>
+        <noise>
+          <type>gaussian</type>
+          <!-- Noise is sampled independently per pixel on each frame.
+               That pixel's noise value is added to each of its color
+               channels, which at that point lie in the range [0,1]. -->
+          <mean>0.0</mean>
+          <stddev>0.007</stddev>
+        </noise>
+      </camera>
+      <plugin name="camera_controller" filename="libgazebo_ros_camera.so">
+        <alwaysOn>true</alwaysOn>
+        <updateRate>0.0</updateRate>
+        <cameraName>/growbot/camera</cameraName>
+        <imageTopicName>image_raw</imageTopicName>
+        <cameraInfoTopicName>camera_info</cameraInfoTopicName>
+        <frameName>camera</frameName>
+        <hackBaseline>0.07</hackBaseline>
+        <distortionK1>0.0</distortionK1>
+        <distortionK2>0.0</distortionK2>
+        <distortionK3>0.0</distortionK3>
+        <distortionT1>0.0</distortionT1>
+        <distortionT2>0.0</distortionT2>
+      </plugin>
+    </sensor>
+  </gazebo>
+
+</robot>
 
diff --git a/urdf/main.xacro b/urdf/main.xacro
index b5fb132..4eb4722 100644
--- a/urdf/main.xacro
+++ b/urdf/main.xacro
@@ -4,8 +4,7 @@
 
     <xacro:include filename="$(find growbot_simulations)/urdf/wheel.xacro" />
     <xacro:include filename="$(find growbot_simulations)/urdf/camera.xacro" />
-    <!--<xacro:include filename="$(find growbot_simulations)/urdf/plugins.xacro" />-->
-    <xacro:include filename="$(find growbot_simulations)/urdf/growbot.gazebo" />
+    <xacro:include filename="$(find growbot_simulations)/urdf/plugins.xacro" />
 
   <material name="silver">
     <color rgba="0.5 0.5 0.5 1"/>
@@ -28,10 +27,10 @@
   <xacro:property name="mass" value="7" />
 
   <!-- dummy link and joint added to fix inertial error per [https://answers.ros.org/question/192817/error-msg-the-root-link_base-has-an-inertia-specified-in-the-urdf-but-kdl/] -->
-  <link name="dummy_link">
+  <link name="dummy">
   </link>
     
-    <link name="chassis_link">
+    <link name="base_link">
         <visual>
             <geometry>
                 <box size="${body_len} ${body_width} ${body_height}"/>
@@ -60,8 +59,8 @@
 
       <!-- dummy link and joint added to fix inertial error per [https://answers.ros.org/question/192817/error-msg-the-root-link_base-has-an-inertia-specified-in-the-urdf-but-kdl/] -->
   <joint name="dummy_joint" type="fixed">
-     <parent link="dummy_link"/>
-     <child link="chassis_link"/>
+     <parent link="dummy"/>
+     <child link="base_link"/>
   </joint>
     
   <xacro:wheel prefix="front_right" x_offset="${wheel_x_offset}" y_offset="${wheel_y_offset}" z_offset="${wheel_z_offset}" width="${wheel_width}" radius="${wheel_diam/2}" y_reflect="-1" />
@@ -71,13 +70,5 @@
   
       <!-- TODO: send variables to camera script to allow for parametric camera size/location -->
   <xacro:camera />
-
-
-    <!-- Add ROS plugin so we can interact with our robot -->
-  <gazebo>
-      <plugin name="gazebo_ros_control" filename="libgazebo_ros_control.so">
-          <robotNamespace>/</robotNamespace>
-      </plugin>
-  </gazebo>
     
 </robot>
diff --git a/urdf/plugins.xacro b/urdf/plugins.xacro
new file mode 100644
index 0000000..ca8baa0
--- /dev/null
+++ b/urdf/plugins.xacro
@@ -0,0 +1,52 @@
+<?xml version="1.0"?>
+<robot>
+
+    <!-- Add ROS plugin so we can interact with our robot -->
+    <gazebo>
+        <plugin name="gazebo_ros_control" filename="libgazebo_ros_control.so">
+            <robotNamespace>/</robotNamespace>
+        </plugin>
+    </gazebo>
+
+  <!--Gazebo Camera Plugin-->
+   <gazebo reference="camera">
+    <sensor type="camera" name="camera">
+      <update_rate>30.0</update_rate>
+      <camera name="head">
+        <horizontal_fov>1.3962634</horizontal_fov>
+        <image>
+          <width>800</width>
+          <height>800</height>
+          <format>R8G8B8</format>
+        </image>
+        <clip>
+          <near>0.02</near>
+          <far>300</far>
+        </clip>
+        <noise>
+          <type>gaussian</type>
+          <!-- Noise is sampled independently per pixel on each frame.
+               That pixel's noise value is added to each of its color
+               channels, which at that point lie in the range [0,1]. -->
+          <mean>0.0</mean>
+          <stddev>0.007</stddev>
+        </noise>
+      </camera>
+      <plugin name="camera_controller" filename="libgazebo_ros_camera.so">
+        <alwaysOn>true</alwaysOn>
+        <updateRate>0.0</updateRate>
+        <cameraName>/growbot/camera</cameraName>
+        <imageTopicName>image_raw</imageTopicName>
+        <cameraInfoTopicName>camera_info</cameraInfoTopicName>
+        <frameName>camera</frameName>
+        <hackBaseline>0.07</hackBaseline>
+        <distortionK1>0.0</distortionK1>
+        <distortionK2>0.0</distortionK2>
+        <distortionK3>0.0</distortionK3>
+        <distortionT1>0.0</distortionT1>
+        <distortionT2>0.0</distortionT2>
+      </plugin>
+    </sensor>
+  </gazebo>
+
+</robot>
diff --git a/urdf/wheel.xacro b/urdf/wheel.xacro
index f37312d..f7ba0a0 100644
--- a/urdf/wheel.xacro
+++ b/urdf/wheel.xacro
@@ -27,9 +27,9 @@
     </link>
 
 
-    <joint name="chassis_to_${prefix}_wheel" type="continuous">
+    <joint name="base_to_${prefix}_wheel" type="continuous">
         <axis xyz="0 1 0"/>
-        <parent link="chassis_link"/>
+        <parent link="base_link"/>
         <child link="${prefix}_wheel"/>
         <origin rpy="0 0 0" xyz="${x_offset} ${y_reflect*y_offset} ${z_offset}"/> <!-- move the child_frame with respect to parent_frame -->
         <limit effort="30" velocity="10"/>
@@ -41,9 +41,12 @@
         <actuator name="$${prefix}_motor">
             <mechanicalReduction>1</mechanicalReduction>
         </actuator>
-        <joint name="chassis_to_${prefix}_wheel">
+        <joint name="base_to_${prefix}_wheel">
             <hardwareInterface>hardware_interface/VelocityJointInterface</hardwareInterface>
         </joint>
     </transmission>
+
+
 </xacro:macro>
-</robot>
\ No newline at end of file
+</robot>
+
diff --git a/worlds/garden.world b/worlds/garden.world
index 6c1cf29..55f5826 100644
--- a/worlds/garden.world
+++ b/worlds/garden.world
@@ -30,11 +30,6 @@
       <ambient>0.4 0.4 0.4 1</ambient>
       <background>0.7 0.7 0.7 1</background>
       <shadows>1</shadows>
-      <sky>
-        <clouds>
-          <speed>12</speed>
-        </clouds>
-      </sky>
     </scene>
     <wind/>
     <spherical_coordinates>
@@ -51,7 +46,7 @@
           <geometry>
             <heightmap>
               <uri>model://heightmap/materials/textures/heightmap.png</uri>
-              <size>16 16 1</size>
+              <size>32 32 1</size>
               <pos>0 0 0</pos>
               <texture>
                 <size>10</size>
@@ -106,7 +101,7 @@
                 <fade_dist>0.5</fade_dist>
               </blend>
               <uri>model://heightmap/materials/textures/heightmap.png</uri>
-              <size>16 16 1</size>
+              <size>32 32 1</size>
               <pos>0 0 0</pos>
             </heightmap>
           </geometry>
