<?xml version="1.0"?>
<robot xmlns:xacro="http://www.ros.org/wiki/xacro" name="growbot">
<xacro:macro name="camera">

    <xacro:property name="camera_link" value="0.05" /> <!-- Size of square 'camera' box -->

    <!-- Camera -->
  <link name="camera_link">
    <collision>
            <origin rpy="0 0 0" xyz="0 0 0"/>
      <geometry>
    <box size="${camera_link} ${camera_link*2} ${camera_link}"/>
      </geometry>
    </collision>

    <visual>
            <origin rpy="0 0 0" xyz="0 0 0"/>
      <geometry>
    <box size="${camera_link} ${camera_link*2} ${camera_link}"/>
      </geometry>
      <material name="black"/>
    </visual>

    <inertial>
      <mass value="1e-5" />
            <origin rpy="0 0 0" xyz="0 0 0"/>
      <inertia ixx="1e-6" ixy="0" ixz="0" iyy="1e-6" iyz="0" izz="1e-6" />
    </inertial>
  </link>

  <!-- generate an optical frame http://www.ros.org/reps/rep-0103.html#suffix-frames
      so that ros and opencv can operate on the camera frame correctly -->
  <joint name="camera_optical_joint" type="fixed">
    <!-- these values have to be these values otherwise the gazebo camera image
        won't be aligned properly with the frame it is supposedly originating from -->
    <origin xyz="0 0 0" rpy="${-pi/2} 0 ${-pi/2}"/>
    <parent link="camera_link"/>
    <child link="camera_link_optical"/>
  </joint>

  <link name="camera_link_optical">
   </link>


    <joint name="chassis_to_camera" type="continuous">
        <axis xyz="0 0 1"/>  <!-- changes axis of rotation -->
        <parent link="chassis_link"/>
        <child link="camera_link"/>
        <origin rpy="0 0 0" xyz="0.15 0 ${camera_link/2 + 0.15}"/> <!-- moves the child_frame with respect to parent_frame -->
        <limit effort="30" velocity="1.0"/>
    </joint>


    <transmission name="camera_transmission">
        <type>transmission_interface/SimpleTransmission</type>
        <actuator name="$camera_motor">
            <mechanicalReduction>1</mechanicalReduction>
        </actuator>
        <joint name="chassis_to_camera">
            <hardwareInterface>hardware_interface/PositionJointInterface</hardwareInterface>
        </joint>
    </transmission>


</xacro:macro>

</robot>

