<?xml version="1.0"?>
<robot xmlns:xacro="http://www.ros.org/wiki/xacro" name="growbot">
<xacro:macro name="wheel" params="prefix x_offset y_offset z_offset width radius y_reflect">

  <!--TODO: make inertial stuff parametric-->
    <!-- rpy (roll pitch yaw) describes rotation in radians -->
    <!-- xyz describes translation in meters -->
    <link name="${prefix}_wheel">
        <visual>
            <origin rpy="${pi/2} 0 0" xyz="0 0 0"/> <!-- set the origin to 0 to recenter the link to the child_frame -->
            <geometry>
                <cylinder length="${width}" radius="${radius}"/>
            </geometry>
                <material name="yellow"/>
        </visual>
        <collision>
            <origin rpy="${pi/2} 0 0" xyz="0 0 0"/> <!-- set the origin to 0 to recenter the link to the child_frame -->
            <geometry>
                <cylinder length="${width}" radius="${radius}"/>
            </geometry>
        </collision>
        <inertial>
            <origin rpy="${pi/2} 0 0" xyz="0 0 0"/> <!-- set the origin to 0 to recenter the link to the child_frame -->
            <mass value="1"/>
            <inertia ixx="0.06" ixy="0.0" ixz="0.0" iyy="0.06" iyz="0.0" izz="0.25"/>
        </inertial>
    </link>


    <joint name="chassis_to_${prefix}_wheel" type="continuous">
        <axis xyz="0 1 0"/>
        <parent link="chassis_link"/>
        <child link="${prefix}_wheel"/>
        <origin rpy="0 0 0" xyz="${x_offset} ${y_reflect*y_offset} ${z_offset}"/> <!-- move the child_frame with respect to parent_frame -->
        <limit effort="30" velocity="10"/>
    </joint>


    <transmission name="${prefix}_wheel_transmission">
        <type>transmission_interface/SimpleTransmission</type>
        <actuator name="$${prefix}_motor">
            <mechanicalReduction>1</mechanicalReduction>
        </actuator>
        <joint name="chassis_to_${prefix}_wheel">
            <hardwareInterface>hardware_interface/VelocityJointInterface</hardwareInterface>
        </joint>
    </transmission>
</xacro:macro>
</robot>